Traceback (most recent call last):
  File "/Users/tomconnolly/programs/miniconda3/envs/data-book/lib/python3.8/site-packages/jupyter_cache/executors/utils.py", line 51, in single_nb_execution
    executenb(
  File "/Users/tomconnolly/programs/miniconda3/envs/data-book/lib/python3.8/site-packages/nbclient/client.py", line 1093, in execute
    return NotebookClient(nb=nb, resources=resources, km=km, **kwargs).execute()
  File "/Users/tomconnolly/programs/miniconda3/envs/data-book/lib/python3.8/site-packages/nbclient/util.py", line 84, in wrapped
    return just_run(coro(*args, **kwargs))
  File "/Users/tomconnolly/programs/miniconda3/envs/data-book/lib/python3.8/site-packages/nbclient/util.py", line 62, in just_run
    return loop.run_until_complete(coro)
  File "/Users/tomconnolly/programs/miniconda3/envs/data-book/lib/python3.8/asyncio/base_events.py", line 616, in run_until_complete
    return future.result()
  File "/Users/tomconnolly/programs/miniconda3/envs/data-book/lib/python3.8/site-packages/nbclient/client.py", line 559, in async_execute
    await self.async_execute_cell(
  File "/Users/tomconnolly/programs/miniconda3/envs/data-book/lib/python3.8/site-packages/nbclient/client.py", line 854, in async_execute_cell
    self._check_raise_for_error(cell, exec_reply)
  File "/Users/tomconnolly/programs/miniconda3/envs/data-book/lib/python3.8/site-packages/nbclient/client.py", line 756, in _check_raise_for_error
    raise CellExecutionError.from_cell_and_msg(cell, exec_reply_content)
nbclient.exceptions.CellExecutionError: An error occurred while executing the following cell:
------------------
plt.figure()
plt.xlim([-1,1])
plt.ylim([-1,1])

plt.xlabel('PC1 loading')
plt.ylabel('PC2 loading')

variables = ['OD','BD','LTD','W']
for i,txt in enumerate(variables):
    plt.plot([0,A[i,0]],[0,A[i,1]],'-')
    plt.text(A[i,0],A[i,1],txt)
------------------

[0;31m---------------------------------------------------------------------------[0m
[0;31mNameError[0m                                 Traceback (most recent call last)
[0;32m/var/folders/67/t9t76vyd78qgn_kwjr1_76yr0000gn/T/ipykernel_17517/1808603681.py[0m in [0;36m<module>[0;34m[0m
[1;32m      8[0m [0mvariables[0m [0;34m=[0m [0;34m[[0m[0;34m'OD'[0m[0;34m,[0m[0;34m'BD'[0m[0;34m,[0m[0;34m'LTD'[0m[0;34m,[0m[0;34m'W'[0m[0;34m][0m[0;34m[0m[0;34m[0m[0m
[1;32m      9[0m [0;32mfor[0m [0mi[0m[0;34m,[0m[0mtxt[0m [0;32min[0m [0menumerate[0m[0;34m([0m[0mvariables[0m[0;34m)[0m[0;34m:[0m[0;34m[0m[0;34m[0m[0m
[0;32m---> 10[0;31m     [0mplt[0m[0;34m.[0m[0mplot[0m[0;34m([0m[0;34m[[0m[0;36m0[0m[0;34m,[0m[0mA[0m[0;34m[[0m[0mi[0m[0;34m,[0m[0;36m0[0m[0;34m][0m[0;34m][0m[0;34m,[0m[0;34m[[0m[0;36m0[0m[0;34m,[0m[0mA[0m[0;34m[[0m[0mi[0m[0;34m,[0m[0;36m1[0m[0;34m][0m[0;34m][0m[0;34m,[0m[0;34m'-'[0m[0;34m)[0m[0;34m[0m[0;34m[0m[0m
[0m[1;32m     11[0m     [0mplt[0m[0;34m.[0m[0mtext[0m[0;34m([0m[0mA[0m[0;34m[[0m[0mi[0m[0;34m,[0m[0;36m0[0m[0;34m][0m[0;34m,[0m[0mA[0m[0;34m[[0m[0mi[0m[0;34m,[0m[0;36m1[0m[0;34m][0m[0;34m,[0m[0mtxt[0m[0;34m)[0m[0;34m[0m[0;34m[0m[0m

[0;31mNameError[0m: name 'A' is not defined
NameError: name 'A' is not defined

